Workbook

Sheet README
A1: Capital Project Submission QA & Weekly Executive Report
A2: Recreated work sample - Brystal Pearson, CAPM - ALL DATA IS SYNTHETIC
A4: What this is | B4: A rebuilt version of work I did as a contract Project Analyst on a multi-region healthcare capital portfolio: routing invoices, POs, and commitment changes for approval, finding why submissions kept getting rejected, fixing it with a standardized pre-submission checklist, and reporting budget position to leadership weekly.
A5: Data | B5: Every project, person, amount, and date is invented. Rejection categories are modeled on the kinds of issues I saw; no client records, files, or screenshots are included.
A6: The story in one line | B6: I stopped fixing rejected submissions one at a time and fixed the template they were built from.
A8: Tab | B8: Purpose
A9: Submission_Log | B9: 96 synthetic submissions over 12 weeks. Weeks 1-6 = before the checklist; weeks 7-12 = after.
A10: Rejection_Pareto | B10: Rejections by reason, before vs. after, with cumulative % - the analysis that pointed to the fix.
A11: PreSubmit_Checklist | B11: The standardized checklist. Each item is tied to the rejection reason it prevents.
A12: Budget_Status | B12: 12 capital projects: approved budget, committed, invoiced, remaining, closeout date, and an automatic flag.
A13: Weekly_Exec_Report | B13: One-page leadership summary. Change the report date (gray cell) and every figure recalculates.
A15: Legend | B15: Gray-filled cells are inputs you can edit. Everything else is a formula or synthetic source data.
A16: Note on results | B16: Before/after figures here come from synthetic data and illustrate the method. They are not measured outcomes from the engagement.

Sheet Weekly_Exec_Report
A1: Weekly Executive Report - Capital Portfolio
A2: Synthetic data. One page, decision-ready.
A4: Report date | C4: 45982
A5: Report week | C5: =MIN(12,MAX(1,INT((C4-DATE(2025,9,1))/7)+1)) -> 12 | D5: Week 1 starts 09/01/2025; capped at week 12 (end of sample data).
A7: 1. BUDGET POSITION
A8: Measure | C8: Value
A9: Approved budget | C9: =Budget_Status!E18 -> 14010000
A10: Committed | C10: =Budget_Status!F18 -> 12072000
A11: Invoiced to date | C11: =Budget_Status!G18 -> 9569000
A12: Uncommitted budget | C12: =Budget_Status!H18 -> 1938000
A13: % of budget committed | C13: =Budget_Status!J18 -> 0.86167024
A15: 2. SUBMISSION QUALITY
A16: Measure | B16: Before checklist (wk 1-6) | C16: After checklist (wk 7-12) | D16: This week
A17: Submissions | B17: =COUNTIFS(Submission_Log!$H$5:$H$100,"No") -> 48 | C17: =COUNTIFS(Submission_Log!$H$5:$H$100,"Yes") -> 48 | D17: =COUNTIFS(Submission_Log!$B$5:$B$100,$C$5) -> 8
A18: Rejected on first pass | B18: =COUNTIFS(Submission_Log!$H$5:$H$100,"No",Submission_Log!$I$5:$I$100,"Rejected") -> 22 | C18: =COUNTIFS(Submission_Log!$H$5:$H$100,"Yes",Submission_Log!$I$5:$I$100,"Rejected") -> 5 | D18: =COUNTIFS(Submission_Log!$B$5:$B$100,$C$5,Submission_Log!$I$5:$I$100,"Rejected") -> 0
A19: First-pass approval rate | B19: =IFERROR(1-B18/B17,0) -> 0.54166667 | C19: =IFERROR(1-C18/C17,0) -> 0.89583333 | D19: =IFERROR(1-D18/D17,0) -> 1
A20: Avg days to final approval | B20: =AVERAGEIFS(Submission_Log!$L$5:$L$100,Submission_Log!$H$5:$H$100,"No") -> 6.9166667 | C20: =AVERAGEIFS(Submission_Log!$L$5:$L$100,Submission_Log!$H$5:$H$100,"Yes") -> 4.3958333 | D20: =IFERROR(AVERAGEIFS(Submission_Log!$L$5:$L$100,Submission_Log!$B$5:$B$100,$C$5),0) -> 3.25
A21: Top rejection reason before checklist: | C21: =INDEX(Rejection_Pareto!B5:B10,MATCH(MAX(Rejection_Pareto!C5:C10),Rejection_Pareto!C5:C10,0)) -> Cost code missing or not on approved budget line
A22: Top rejection reason after checklist: | C22: =INDEX(Rejection_Pareto!B5:B10,MATCH(MAX(Rejection_Pareto!F5:F10),Rejection_Pareto!F5:F10,0)) -> Amount exceeds remaining commitment balance
A24: 3. PROJECTS NEEDING ATTENTION
A25: Flagged projects: | C25: =COUNTIF(Budget_Status!M6:M17,"?*") -> 4
A26: Project ID | B26: Project | C26: Owner | D26: Flag | E26: Open Commitment ($)
A27: =Budget_Status!A6 -> CP-2401 | B27: =Budget_Status!B6 -> Central - OR Renovation | C27: =Budget_Status!D6 -> J. Alvarez | D27: =IF(Budget_Status!M6="","-",Budget_Status!M6) -> - | E27: =Budget_Status!I6 -> 123000
A28: =Budget_Status!A7 -> CP-2402 | B28: =Budget_Status!B7 -> East - Imaging Suite | C28: =Budget_Status!D7 -> K. Brooks | D28: =IF(Budget_Status!M7="","-",Budget_Status!M7) -> - | E28: =Budget_Status!I7 -> 582000
A29: =Budget_Status!A8 -> CP-2403 | B29: =Budget_Status!B8 -> West - HVAC Replacement | C29: =Budget_Status!D8 -> S. Patel | D29: =IF(Budget_Status!M8="","-",Budget_Status!M8) -> - | E29: =Budget_Status!I8 -> 293000
A30: =Budget_Status!A9 -> CP-2404 | B30: =Budget_Status!B9 -> Central - ED Expansion | C30: =Budget_Status!D9 -> D. Okafor | D30: =IF(Budget_Status!M9="","-",Budget_Status!M9) -> Over 95% committed | E30: =Budget_Status!I9 -> 472000
A31: =Budget_Status!A10 -> CP-2405 | B31: =Budget_Status!B10 -> East - Roof Replacement | C31: =Budget_Status!D10 -> J. Alvarez | D31: =IF(Budget_Status!M10="","-",Budget_Status!M10) -> - | E31: =Budget_Status!I10 -> 356000
A32: =Budget_Status!A11 -> CP-2406 | B32: =Budget_Status!B11 -> West - Pharmacy Upgrade | C32: =Budget_Status!D11 -> J. Alvarez | D32: =IF(Budget_Status!M11="","-",Budget_Status!M11) -> - | E32: =Budget_Status!I11 -> 82000
A33: =Budget_Status!A12 -> CP-2407 | B33: =Budget_Status!B12 -> Central - Generator Install | C33: =Budget_Status!D12 -> S. Patel | D33: =IF(Budget_Status!M12="","-",Budget_Status!M12) -> Closeout overdue | E33: =Budget_Status!I12 -> 23000
A34: =Budget_Status!A13 -> CP-2408 | B34: =Budget_Status!B13 -> East - Lab Remodel | C34: =Budget_Status!D13 -> K. Brooks | D34: =IF(Budget_Status!M13="","-",Budget_Status!M13) -> Over 95% committed | E34: =Budget_Status!I13 -> 149000
A35: =Budget_Status!A14 -> CP-2409 | B35: =Budget_Status!B14 -> West - Parking Structure | C35: =Budget_Status!D14 -> K. Brooks | D35: =IF(Budget_Status!M14="","-",Budget_Status!M14) -> - | E35: =Budget_Status!I14 -> 132000
A36: =Budget_Status!A15 -> CP-2410 | B36: =Budget_Status!B15 -> Central - Patient Tower Refresh | C36: =Budget_Status!D15 -> M. Chen | D36: =IF(Budget_Status!M15="","-",Budget_Status!M15) -> Closeout overdue | E36: =Budget_Status!I15 -> 102000
A37: =Budget_Status!A16 -> CP-2411 | B37: =Budget_Status!B16 -> East - Sterile Processing | C37: =Budget_Status!D16 -> S. Patel | D37: =IF(Budget_Status!M16="","-",Budget_Status!M16) -> - | E37: =Budget_Status!I16 -> 0
A38: =Budget_Status!A17 -> CP-2412 | B38: =Budget_Status!B17 -> West - Clinic Build-Out | C38: =Budget_Status!D17 -> M. Chen | D38: =IF(Budget_Status!M17="","-",Budget_Status!M17) -> - | E38: =Budget_Status!I17 -> 189000
A40: 4. DECISIONS / ASKS FOR LEADERSHIP
A41: 1. Approve a quarterly budget-line refresh so R2 (over remaining balance) stops recurring.
A42: 2. Publish an approver routing matrix by amount and region to close out R5.
A43: 3. Confirm owners and revised dates for every project flagged 'Closeout overdue'.

Sheet Submission_Log
A1: Submission Log
A2: Synthetic. Checklist introduced at week 7.
A4: Submission ID | B4: Week | C4: Submitted | D4: Project ID | E4: Doc Type | F4: Amount ($) | G4: Submitted By | H4: Checklist Used | I4: First-Pass Outcome | J4: Rejection Reason | K4: Resubmissions | L4: Days to Final Approval
A5: S-1001 | B5: 1 | C5: 45902 | D5: CP-2411 | E5: Commitment Change | F5: 42700 | G5: J. Alvarez | H5: No | I5: Rejected | J5: Required backup missing (signed pay app, lien waiver) | K5: 1 | L5: 6
A6: S-1002 | B6: 1 | C6: 45902 | D6: CP-2406 | E6: PO | F6: 51100 | G6: D. Okafor | H6: No | I6: Rejected | J6: Retainage or math error | K6: 1 | L6: 11
A7: S-1003 | B7: 1 | C7: 45903 | D7: CP-2407 | E7: PO | F7: 29100 | G7: S. Patel | H7: No | I7: Rejected | J7: Required backup missing (signed pay app, lien waiver) | K7: 1 | L7: 14
A8: S-1004 | B8: 1 | C8: 45904 | D8: CP-2407 | E8: Commitment Change | F8: 74300 | G8: J. Alvarez | H8: No | I8: Rejected | J8: Retainage or math error | K8: 1 | L8: 14
A9: S-1005 | B9: 1 | C9: 45904 | D9: CP-2401 | E9: Invoice | F9: 30900 | G9: D. Okafor | H9: No | I9: Rejected | J9: PO number missing or does not match commitment | K9: 1 | L9: 7
A10: S-1006 | B10: 1 | C10: 45901 | D10: CP-2410 | E10: PO | F10: 97100 | G10: S. Patel | H10: No | I10: Approved | K10: 0 | L10: 2
A11: S-1007 | B11: 1 | C11: 45901 | D11: CP-2405 | E11: Invoice | F11: 23600 | G11: M. Chen | H11: No | I11: Approved | K11: 0 | L11: 5
A12: S-1008 | B12: 1 | C12: 45905 | D12: CP-2409 | E12: Invoice | F12: 93400 | G12: K. Brooks | H12: No | I12: Rejected | J12: PO number missing or does not match commitment | K12: 1 | L12: 14
A13: S-1009 | B13: 2 | C13: 45912 | D13: CP-2403 | E13: Invoice | F13: 138200 | G13: M. Chen | H13: No | I13: Approved | K13: 0 | L13: 2
A14: S-1010 | B14: 2 | C14: 45909 | D14: CP-2408 | E14: Invoice | F14: 23700 | G14: J. Alvarez | H14: No | I14: Approved | K14: 0 | L14: 4
A15: S-1011 | B15: 2 | C15: 45912 | D15: CP-2404 | E15: Commitment Change | F15: 170700 | G15: K. Brooks | H15: No | I15: Rejected | J15: Amount exceeds remaining commitment balance | K15: 1 | L15: 7
A16: S-1012 | B16: 2 | C16: 45909 | D16: CP-2403 | E16: PO | F16: 170600 | G16: S. Patel | H16: No | I16: Rejected | J16: Amount exceeds remaining commitment balance | K16: 1 | L16: 12
A17: S-1013 | B17: 2 | C17: 45911 | D17: CP-2404 | E17: Invoice | F17: 74200 | G17: S. Patel | H17: No | I17: Approved | K17: 0 | L17: 4
A18: S-1014 | B18: 2 | C18: 45909 | D18: CP-2408 | E18: Invoice | F18: 47600 | G18: S. Patel | H18: No | I18: Rejected | J18: Cost code missing or not on approved budget line | K18: 1 | L18: 14
A19: S-1015 | B19: 2 | C19: 45908 | D19: CP-2404 | E19: Invoice | F19: 16500 | G19: J. Alvarez | H19: No | I19: Approved | K19: 0 | L19: 3
A20: S-1016 | B20: 2 | C20: 45909 | D20: CP-2406 | E20: Invoice | F20: 94500 | G20: S. Patel | H20: No | I20: Rejected | J20: Amount exceeds remaining commitment balance | K20: 1 | L20: 14
A21: S-1017 | B21: 3 | C21: 45916 | D21: CP-2410 | E21: PO | F21: 46800 | G21: J. Alvarez | H21: No | I21: Approved | K21: 0 | L21: 5
A22: S-1018 | B22: 3 | C22: 45915 | D22: CP-2402 | E22: PO | F22: 66400 | G22: J. Alvarez | H22: No | I22: Approved | K22: 0 | L22: 2
A23: S-1019 | B23: 3 | C23: 45918 | D23: CP-2407 | E23: Invoice | F23: 144900 | G23: K. Brooks | H23: No | I23: Rejected | J23: Cost code missing or not on approved budget line | K23: 1 | L23: 14
A24: S-1020 | B24: 3 | C24: 45919 | D24: CP-2407 | E24: Invoice | F24: 53000 | G24: J. Alvarez | H24: No | I24: Rejected | J24: Routed to wrong approver | K24: 1 | L24: 13
A25: S-1021 | B25: 3 | C25: 45916 | D25: CP-2401 | E25: Commitment Change | F25: 151100 | G25: D. Okafor | H25: No | I25: Approved | K25: 0 | L25: 3
A26: S-1022 | B26: 3 | C26: 45916 | D26: CP-2408 | E26: PO | F26: 41600 | G26: D. Okafor | H26: No | I26: Approved | K26: 0 | L26: 2
A27: S-1023 | B27: 3 | C27: 45917 | D27: CP-2401 | E27: PO | F27: 50700 | G27: D. Okafor | H27: No | I27: Approved | K27: 0 | L27: 5
A28: S-1024 | B28: 3 | C28: 45915 | D28: CP-2409 | E28: PO | F28: 31200 | G28: M. Chen | H28: No | I28: Rejected | J28: Retainage or math error | K28: 1 | L28: 14
A29: S-1025 | B29: 4 | C29: 45922 | D29: CP-2401 | E29: Invoice | F29: 106800 | G29: S. Patel | H29: No | I29: Approved | K29: 0 | L29: 3
A30: S-1026 | B30: 4 | C30: 45922 | D30: CP-2402 | E30: Invoice | F30: 16100 | G30: S. Patel | H30: No | I30: Rejected | J30: Routed to wrong approver | K30: 1 | L30: 12
A31: S-1027 | B31: 4 | C31: 45926 | D31: CP-2404 | E31: Commitment Change | F31: 108600 | G31: S. Patel | H31: No | I31: Approved | K31: 0 | L31: 5
A32: S-1028 | B32: 4 | C32: 45924 | D32: CP-2409 | E32: Invoice | F32: 168500 | G32: D. Okafor | H32: No | I32: Rejected | J32: PO number missing or does not match commitment | K32: 1 | L32: 9
A33: S-1029 | B33: 4 | C33: 45922 | D33: CP-2403 | E33: Invoice | F33: 84500 | G33: D. Okafor | H33: No | I33: Approved | K33: 0 | L33: 2
A34: S-1030 | B34: 4 | C34: 45923 | D34: CP-2410 | E34: Commitment Change | F34: 179300 | G34: M. Chen | H34: No | I34: Rejected | J34: Cost code missing or not on approved budget line | K34: 1 | L34: 10
A35: S-1031 | B35: 4 | C35: 45926 | D35: CP-2402 | E35: Invoice | F35: 69000 | G35: S. Patel | H35: No | I35: Rejected | J35: Required backup missing (signed pay app, lien waiver) | K35: 1 | L35: 10
A36: S-1032 | B36: 4 | C36: 45924 | D36: CP-2401 | E36: Commitment Change | F36: 56700 | G36: J. Alvarez | H36: No | I36: Approved | K36: 0 | L36: 3
A37: S-1033 | B37: 5 | C37: 45930 | D37: CP-2402 | E37: Commitment Change | F37: 31400 | G37: M. Chen | H37: No | I37: Rejected | J37: Cost code missing or not on approved budget line | K37: 1 | L37: 11
A38: S-1034 | B38: 5 | C38: 45929 | D38: CP-2409 | E38: PO | F38: 48200 | G38: D. Okafor | H38: No | I38: Approved | K38: 0 | L38: 2
A39: S-1035 | B39: 5 | C39: 45930 | D39: CP-2405 | E39: Invoice | F39: 4600 | G39: D. Okafor | H39: No | I39: Approved | K39: 0 | L39: 4
A40: S-1036 | B40: 5 | C40: 45933 | D40: CP-2409 | E40: PO | F40: 102700 | G40: J. Alvarez | H40: No | I40: Rejected | J40: Retainage or math error | K40: 1 | L40: 8
A41: S-1037 | B41: 5 | C41: 45931 | D41: CP-2406 | E41: Commitment Change | F41: 101200 | G41: M. Chen | H41: No | I41: Approved | K41: 0 | L41: 2
...

Sheet Rejection_Pareto
A1: Rejection Pareto - Before vs. After Checklist
A2: Before = weeks 1-6 (no checklist). After = weeks 7-12.
A4: Code | B4: Rejection Reason | C4: Before | D4: % of Before | E4: Cumulative % (Before) | F4: After | G4: Change
A5: R1 | B5: Cost code missing or not on approved budget line | C5: =COUNTIFS(Submission_Log!$J$5:$J$100,B5,Submission_Log!$H$5:$H$100,"No") -> 5 | D5: =IFERROR(C5/$C$11,0) -> 0.22727273 | E5: =SUM($D$5:D5) -> 0.22727273 | F5: =COUNTIFS(Submission_Log!$J$5:$J$100,B5,Submission_Log!$H$5:$H$100,"Yes") -> 0 | G5: =F5-C5 -> -5
A6: R4 | B6: Required backup missing (signed pay app, lien waiver) | C6: =COUNTIFS(Submission_Log!$J$5:$J$100,B6,Submission_Log!$H$5:$H$100,"No") -> 4 | D6: =IFERROR(C6/$C$11,0) -> 0.18181818 | E6: =SUM($D$5:D6) -> 0.40909091 | F6: =COUNTIFS(Submission_Log!$J$5:$J$100,B6,Submission_Log!$H$5:$H$100,"Yes") -> 0 | G6: =F6-C6 -> -4
A7: R6 | B7: Retainage or math error | C7: =COUNTIFS(Submission_Log!$J$5:$J$100,B7,Submission_Log!$H$5:$H$100,"No") -> 4 | D7: =IFERROR(C7/$C$11,0) -> 0.18181818 | E7: =SUM($D$5:D7) -> 0.59090909 | F7: =COUNTIFS(Submission_Log!$J$5:$J$100,B7,Submission_Log!$H$5:$H$100,"Yes") -> 1 | G7: =F7-C7 -> -3
A8: R2 | B8: Amount exceeds remaining commitment balance | C8: =COUNTIFS(Submission_Log!$J$5:$J$100,B8,Submission_Log!$H$5:$H$100,"No") -> 3 | D8: =IFERROR(C8/$C$11,0) -> 0.13636364 | E8: =SUM($D$5:D8) -> 0.72727273 | F8: =COUNTIFS(Submission_Log!$J$5:$J$100,B8,Submission_Log!$H$5:$H$100,"Yes") -> 2 | G8: =F8-C8 -> -1
A9: R3 | B9: PO number missing or does not match commitment | C9: =COUNTIFS(Submission_Log!$J$5:$J$100,B9,Submission_Log!$H$5:$H$100,"No") -> 3 | D9: =IFERROR(C9/$C$11,0) -> 0.13636364 | E9: =SUM($D$5:D9) -> 0.86363636 | F9: =COUNTIFS(Submission_Log!$J$5:$J$100,B9,Submission_Log!$H$5:$H$100,"Yes") -> 0 | G9: =F9-C9 -> -3
A10: R5 | B10: Routed to wrong approver | C10: =COUNTIFS(Submission_Log!$J$5:$J$100,B10,Submission_Log!$H$5:$H$100,"No") -> 3 | D10: =IFERROR(C10/$C$11,0) -> 0.13636364 | E10: =SUM($D$5:D10) -> 1 | F10: =COUNTIFS(Submission_Log!$J$5:$J$100,B10,Submission_Log!$H$5:$H$100,"Yes") -> 2 | G10: =F10-C10 -> -1
B11: Total rejections | C11: =SUM(C5:C10) -> 22 | F11: =SUM(F5:F10) -> 5 | G11: =F11-C11 -> -17
A13: Read it this way:
A14: The top three reasons by count were preventable before submission - they were template problems, not people problems. That is what the checklist targets.
A15: R2 and R5 persist after: budget balance and approver changes happen upstream, so they need a budget refresh and a routing matrix, not just a checklist.

Sheet PreSubmit_Checklist
A1: Pre-Submission Checklist
A2: Completed by the submitter before routing. Analyst confirms before it moves forward.
A4: # | B4: Check | C4: How to verify | D4: Prevents | E4: Done (Y/N)
A5: 1 | B5: Cost code matches an approved budget line | C5: Compare to current budget line list for the project | D5: R1 | E5: Y
A6: 2 | B6: Amount is within the remaining commitment balance | C6: Remaining = commitment - invoiced to date; pull from Budget_Status | D6: R2
A7: 3 | B7: PO number present and matches the commitment | C7: Match PO on document to commitment record | D7: R3
A8: 4 | B8: Signed pay application attached | C8: Contractor and architect signatures present | D8: R4
A9: 5 | B9: Conditional lien waiver attached for this period | C9: Period and amount match the pay application | D9: R4
A10: 6 | B10: Approver matches the routing matrix for this amount and region | C10: Check threshold tier before routing | D10: R5
A11: 7 | B11: Retainage calculated at contract rate | C11: Recalculate; line totals tie to the summary | D11: R6
A12: 8 | B12: Document type and project ID are correct | C12: Matches project record exactly | D12: R1
B14: Items complete | E14: =COUNTIF(E5:E12,"Y")&" of "&COUNTA(B5:B12) -> 1 of 8
B15: Ready to route? | E15: =IF(COUNTIF(E5:E12,"Y")=COUNTA(B5:B12),"YES - route","NO - hold") -> NO - hold
B17: Example row: enter Y or N in the gray cells. All eight must be Y before a submission routes.

Sheet Budget_Status
A1: Capital Project Budget Status
A2: Synthetic. Amounts in dollars.
A3: Report date: | B3: =Weekly_Exec_Report!C4 -> 45982
A5: Project ID | B5: Project | C5: Region | D5: Owner | E5: Approved Budget ($) | F5: Committed ($) | G5: Invoiced to Date ($) | H5: Uncommitted Budget ($) | I5: Open Commitment ($) | J5: % Committed | K5: Status | L5: Target Closeout | M5: Flag
A6: CP-2401 | B6: Central - OR Renovation | C6: Central | D6: J. Alvarez | E6: 480000 | F6: 377000 | G6: 254000 | H6: =E6-F6 -> 103000 | I6: =F6-G6 -> 123000 | J6: =IFERROR(F6/E6,0) -> 0.78541667 | K6: Active | L6: 46042 | M6: =IF(K6="Closed","",IF(AND(L6<$B$3,K6<>"Closed"),"Closeout overdue",IF(J6>=0.95,"Over 95% committed",IF(L6-$B$3<=30,"Closeout within 30 days",""))))
A7: CP-2402 | B7: East - Imaging Suite | C7: East | D7: K. Brooks | E7: 2800000 | F7: 2238000 | G7: 1656000 | H7: =E7-F7 -> 562000 | I7: =F7-G7 -> 582000 | J7: =IFERROR(F7/E7,0) -> 0.79928571 | K7: Active | L7: 46030 | M7: =IF(K7="Closed","",IF(AND(L7<$B$3,K7<>"Closed"),"Closeout overdue",IF(J7>=0.95,"Over 95% committed",IF(L7-$B$3<=30,"Closeout within 30 days",""))))
A8: CP-2403 | B8: West - HVAC Replacement | C8: West | D8: S. Patel | E8: 750000 | F8: 668000 | G8: 375000 | H8: =E8-F8 -> 82000 | I8: =F8-G8 -> 293000 | J8: =IFERROR(F8/E8,0) -> 0.89066667 | K8: Active | L8: 46173 | M8: =IF(K8="Closed","",IF(AND(L8<$B$3,K8<>"Closed"),"Closeout overdue",IF(J8>=0.95,"Over 95% committed",IF(L8-$B$3<=30,"Closeout within 30 days",""))))
A9: CP-2404 | B9: Central - ED Expansion | C9: Central | D9: D. Okafor | E9: 1500000 | F9: 1485000 | G9: 1013000 | H9: =E9-F9 -> 15000 | I9: =F9-G9 -> 472000 | J9: =IFERROR(F9/E9,0) -> 0.99 | K9: Active | L9: 46047 | M9: =IF(K9="Closed","",IF(AND(L9<$B$3,K9<>"Closed"),"Closeout overdue",IF(J9>=0.95,"Over 95% committed",IF(L9-$B$3<=30,"Closeout within 30 days","")))) -> Over 95% committed
A10: CP-2405 | B10: East - Roof Replacement | C10: East | D10: J. Alvarez | E10: 1200000 | F10: 1009000 | G10: 653000 | H10: =E10-F10 -> 191000 | I10: =F10-G10 -> 356000 | J10: =IFERROR(F10/E10,0) -> 0.84083333 | K10: Active | L10: 46033 | M10: =IF(K10="Closed","",IF(AND(L10<$B$3,K10<>"Closed"),"Closeout overdue",IF(J10>=0.95,"Over 95% committed",IF(L10-$B$3<=30,"Closeout within 30 days",""))))
A11: CP-2406 | B11: West - Pharmacy Upgrade | C11: West | D11: J. Alvarez | E11: 1500000 | F11: 1202000 | G11: 1120000 | H11: =E11-F11 -> 298000 | I11: =F11-G11 -> 82000 | J11: =IFERROR(F11/E11,0) -> 0.80133333 | K11: Closeout | L11: 46074 | M11: =IF(K11="Closed","",IF(AND(L11<$B$3,K11<>"Closed"),"Closeout overdue",IF(J11>=0.95,"Over 95% committed",IF(L11-$B$3<=30,"Closeout within 30 days",""))))
A12: CP-2407 | B12: Central - Generator Install | C12: Central | D12: S. Patel | E12: 2100000 | F12: 1886000 | G12: 1863000 | H12: =E12-F12 -> 214000 | I12: =F12-G12 -> 23000 | J12: =IFERROR(F12/E12,0) -> 0.89809524 | K12: Closeout | L12: 45941 | M12: =IF(K12="Closed","",IF(AND(L12<$B$3,K12<>"Closed"),"Closeout overdue",IF(J12>=0.95,"Over 95% committed",IF(L12-$B$3<=30,"Closeout within 30 days","")))) -> Closeout overdue
A13: CP-2408 | B13: East - Lab Remodel | C13: East | D13: K. Brooks | E13: 900000 | F13: 866000 | G13: 717000 | H13: =E13-F13 -> 34000 | I13: =F13-G13 -> 149000 | J13: =IFERROR(F13/E13,0) -> 0.96222222 | K13: Active | L13: 46154 | M13: =IF(K13="Closed","",IF(AND(L13<$B$3,K13<>"Closed"),"Closeout overdue",IF(J13>=0.95,"Over 95% committed",IF(L13-$B$3<=30,"Closeout within 30 days","")))) -> Over 95% committed
A14: CP-2409 | B14: West - Parking Structure | C14: West | D14: K. Brooks | E14: 480000 | F14: 379000 | G14: 247000 | H14: =E14-F14 -> 101000 | I14: =F14-G14 -> 132000 | J14: =IFERROR(F14/E14,0) -> 0.78958333 | K14: Active | L14: 46027 | M14: =IF(K14="Closed","",IF(AND(L14<$B$3,K14<>"Closed"),"Closeout overdue",IF(J14>=0.95,"Over 95% committed",IF(L14-$B$3<=30,"Closeout within 30 days",""))))
A15: CP-2410 | B15: Central - Patient Tower Refresh | C15: Central | D15: M. Chen | E15: 480000 | F15: 415000 | G15: 313000 | H15: =E15-F15 -> 65000 | I15: =F15-G15 -> 102000 | J15: =IFERROR(F15/E15,0) -> 0.86458333 | K15: Closeout | L15: 45964 | M15: =IF(K15="Closed","",IF(AND(L15<$B$3,K15<>"Closed"),"Closeout overdue",IF(J15>=0.95,"Over 95% committed",IF(L15-$B$3<=30,"Closeout within 30 days","")))) -> Closeout overdue
A16: CP-2411 | B16: East - Sterile Processing | C16: East | D16: S. Patel | E16: 1200000 | F16: 991000 | G16: 991000 | H16: =E16-F16 -> 209000 | I16: =F16-G16 -> 0 | J16: =IFERROR(F16/E16,0) -> 0.82583333 | K16: Closed | L16: 45968 | M16: =IF(K16="Closed","",IF(AND(L16<$B$3,K16<>"Closed"),"Closeout overdue",IF(J16>=0.95,"Over 95% committed",IF(L16-$B$3<=30,"Closeout within 30 days",""))))
A17: CP-2412 | B17: West - Clinic Build-Out | C17: West | D17: M. Chen | E17: 620000 | F17: 556000 | G17: 367000 | H17: =E17-F17 -> 64000 | I17: =F17-G17 -> 189000 | J17: =IFERROR(F17/E17,0) -> 0.89677419 | K17: Closeout | L17: 46104 | M17: =IF(K17="Closed","",IF(AND(L17<$B$3,K17<>"Closed"),"Closeout overdue",IF(J17>=0.95,"Over 95% committed",IF(L17-$B$3<=30,"Closeout within 30 days",""))))
B18: Portfolio total | E18: =SUM(E6:E17) -> 14010000 | F18: =SUM(F6:F17) -> 12072000 | G18: =SUM(G6:G17) -> 9569000 | H18: =SUM(H6:H17) -> 1938000 | I18: =SUM(I6:I17) -> 2503000 | J18: =IFERROR(F18/E18,0) -> 0.86167024
